<?xml version="1.0" ?>
<!-- =================================================================================== -->
<!-- |    This document was autogenerated by xacro from Fish1.xacro                    | -->
<!-- |    EDITING THIS FILE BY HAND IS NOT RECOMMENDED                                 | -->
<!-- =================================================================================== -->
<robot name="flag1" xmlns:xacro="http://www.ros.org/wiki/xacro">
  <link name="base_link"> </link>

  <link name="first_link">
    <visual>
      <origin rpy="0 0 0" xyz="0 0 0"/>
      <geometry>
        <mesh filename=""/>
      </geometry>
    </visual>
  </link>


<joint name="Slew" type="revolute">
    <parent link="base_link"/>
    <child link="first_link"/>
    <axis xyz="0 0 -1"/>
    <origin rpy="0 0 0" xyz="0 0 0"/>
    <limit effort="1000.0" lower="-0.5" upper="0.5" velocity="1.0"/>
</joint>
</robot>
