<?xml version="1.0" ?>
<!-- =================================================================================== -->
<!-- |    This document was autogenerated by xacro from Fish2.xacro                    | -->
<!-- |    EDITING THIS FILE BY HAND IS NOT RECOMMENDED                                 | -->
<!-- =================================================================================== -->
<robot name="fish5" xmlns:xacro="http://www.ros.org/wiki/xacro">
  <link name="base_link">
    <visual>
      <origin rpy="0 0 0" xyz="0 0 0"/>
      <geometry>
        <mesh filename="robot/Fish5/Fish5_1_new.obj"/>
      </geometry>
    </visual>
  </link>

  <link name="body">
    <visual>
      <origin rpy="0 0 0" xyz="0 0 0"/>
      <geometry>
        <mesh filename="robot/Fish5/Fish5_2_new.obj"/>
      </geometry>
    </visual>
  </link>

  <joint name="Slew" type="continuous">
    <parent link="base_link"/>
    <child link="body"/>
    <axis xyz="0 0 1"/>
    <origin rpy="0 0 0" xyz="0 0 0"/>
    <limit effort="1000.0" lower="-0.5488" upper="0.5488" velocity="1.0"/>
  </joint>

  <link name="tail">
    <visual>
      <origin rpy="0 0 0" xyz="0 0 0"/>
      <geometry>
        <mesh filename="robot/Fish5/Fish5_Tail1_new.obj"/>
      </geometry>
    </visual>
  </link>

  <joint name="Shoulder" type="continuous">
    <parent link="body"/>
    <child link="tail"/>
    <axis xyz="0 0 1"/>
    <origin rpy="0 0 0" xyz="-6 0 0"/>
    <limit effort="1000.0" lower="-0.5488" upper="0.5488" velocity="1.0"/>
  </joint>

  <link name="fin">
    <visual>
      <origin rpy="0 0 0" xyz="0 0 0"/>
      <geometry>
        <mesh filename="robot/Fish5/Fish5_Fin_new1.obj"/>
      </geometry>
    </visual>
  </link>

  <joint name="Elbow" type="continuous">
    <parent link="body"/>
    <child link="fin"/>
    <axis xyz="1 0 0"/>
    <origin rpy="0 0 0" xyz="-0.5 0 2.1"/>
    <limit effort="1000.0" lower="-0.5" upper="0.5" velocity="1.0"/>
  </joint>
</robot>
