<?xml version="1.0" ?>
<!-- =================================================================================== -->
<!-- |    This document was autogenerated by xacro from Fish1.xacro                    | -->
<!-- |    EDITING THIS FILE BY HAND IS NOT RECOMMENDED                                 | -->
<!-- =================================================================================== -->
<robot name="fish1" xmlns:xacro="http://www.ros.org/wiki/xacro">
  <link name="base_link">
    <visual>
      <origin rpy="0 0 0" xyz="0 0 0"/>
      <geometry>
        <mesh filename="package://uwsim_models/uwsim_fish_urdf/Fish_models/Fish_swarm_Leadfish.dae"/>
      </geometry>
    </visual>
  </link>

  <link name="swarm">
    <visual>
      <origin rpy="0 0 0" xyz="0 0 0"/>
      <geometry>
        <mesh filename="package://uwsim_models/uwsim_fish_urdf/Fish_models/Fish_swarm2_silver.dae"/>
      </geometry>
    </visual>
  </link>

  <joint name="Slew" type="revolute">
    <parent link="base_link"/>
    <child link="swarm"/>
    <axis xyz="0 0 1"/>
    <origin rpy="0 0 0" xyz="-10 0 0"/>
    <limit effort="1000.0" lower="-0.5" upper="0.5" velocity="1.0"/>
  </joint>

  <link name="tail_fish">
    <visual>
      <origin rpy="0 0 0" xyz="0 0 0"/>
      <geometry>
        <mesh filename="package://uwsim_models/uwsim_fish_urdf/Fish_models/Fish_swarm_Tailfish.dae"/>
      </geometry>
    </visual>
  </link>

  <joint name="Shoulder" type="revolute">
    <parent link="base_link"/>
    <child link="tail_fish"/>
    <axis xyz="0 0 1"/>
    <origin rpy="0 0 0" xyz="-20 0 0"/>
    <limit effort="1000.0" lower="-0.5" upper="0.5" velocity="1.0"/>
  </joint>

</robot>

