<?xml version="1.0" ?>
<!-- =================================================================================== -->
<!-- |    This document was autogenerated by xacro from Fish4.xacro                    | -->
<!-- |    EDITING THIS FILE BY HAND IS NOT RECOMMENDED                                 | -->
<!-- =================================================================================== -->
<robot name="fish4" xmlns:xacro="http://www.ros.org/wiki/xacro">
  <link name="base_link">
    <visual>
      <origin rpy="0 0 0" xyz="0 0 0"/>
      <geometry>
        <mesh filename="package://uwsim_models/uwsim_fish_urdf/Fish_models/Fish4_1.dae"/>
      </geometry>
    </visual>
  </link>

  <link name="body">
    <visual>
      <origin rpy="0 0 0" xyz="0 0 0"/>
      <geometry>
        <mesh filename="package://uwsim_models/uwsim_fish_urdf/Fish_models/Fish4_2.dae"/>
      </geometry>
    </visual>
  </link>

  <joint name="Slew" type="continuous">
    <parent link="base_link"/>
    <child link="body"/>
    <axis xyz="0 0 1"/>
    <origin rpy="0 0 0" xyz="0 0 0"/>
    <limit effort="1000.0" lower="-0.5488" upper="0.5488" velocity="1.0"/>
  </joint>

  <link name="tail">
    <visual>
      <origin rpy="0 0 0" xyz="0 0 0"/>
      <geometry>
        <mesh filename="package://uwsim_models/uwsim_fish_urdf/Fish_models/Fish4_Tail.dae"/>
      </geometry>
    </visual>
  </link>

  <joint name="Shoulder" type="continuous">
    <parent link="body"/>
    <child link="tail"/>
    <axis xyz="0 0 1"/>
    <origin rpy="0 0 0" xyz="0 -2.2 0"/>
    <limit effort="1000.0" lower="-0.5488" upper="0.5488" velocity="1.0"/>
  </joint>
</robot>
