<?xml version="1.0" ?>
<!-- =================================================================================== -->
<!-- |    This document was autogenerated by xacro from Fish2.xacro                    | -->
<!-- |    EDITING THIS FILE BY HAND IS NOT RECOMMENDED                                 | -->
<!-- =================================================================================== -->
<robot name="fish2" xmlns:xacro="http://www.ros.org/wiki/xacro">
  <link name="base_link"> <!--actual body , for simplification renamed -->
    <visual>
      <origin rpy="0 0 0" xyz="0 0 0"/>
      <geometry>
        <mesh filename="package://uwsim_models/uwsim_fish_urdf/Fish_models/Shark1_body_1.dae"/>
      </geometry>
    </visual>
  </link>

  <link name="body"> <!--actual tail , for simplification renamed -->
    <visual>
      <origin rpy="0 0 0" xyz="0 0 0"/>
      <geometry>
        <mesh filename="package://uwsim_models/uwsim_fish_urdf/Fish_models/Shark1_tail.dae"/>
      </geometry>
    </visual>
  </link>

  <joint name="Slew" type="continuous">
    <parent link="base_link"/>
    <child link="body"/>
    <axis xyz="0 0 -1"/>
    <origin rpy="0 0 0" xyz="-6.74 0 0"/>
    <limit effort="1000.0" lower="-0.5488" upper="0.5488" velocity="1.0"/>
  </joint>

  <link name="tail"> <!--actual fin , for simplification renamed -->
    <visual>
      <origin rpy="0 0 0" xyz="0 0 0"/>
      <geometry>
        <mesh filename="package://uwsim_models/uwsim_fish_urdf/Fish_models/Shark1_fin.dae"/>
      </geometry>
    </visual>
  </link>

  <joint name="Shoulder" type="continuous">
    <parent link="base_link"/>
    <child link="tail"/>
    <axis xyz="1 0 0"/>
    <origin rpy="0 0 3.14" xyz="-2 0 0.67659"/>
    <limit effort="1000.0" lower="-0.5488" upper="0.5488" velocity="1.0"/>
  </joint>
</robot>
