<?xml version="1.0" ?>
<!-- =================================================================================== -->
<!-- |    This document was autogenerated by xacro from g500ARM5.urdf.xacro            | -->
<!-- |    EDITING THIS FILE BY HAND IS NOT RECOMMENDED                                 | -->
<!-- =================================================================================== -->
<robot name="Nessie_sample" xmlns:xacro="http://www.ros.org/wiki/xacro">
  <link name="base_link">
    <visual>
      <origin rpy="0 0 0" xyz="0 0 0"/>
      <geometry>
        <mesh filename="robot/UW_Vehicle/UWVehicle_Nessie_new1.3ds"/>
      </geometry>
    </visual>
  </link>

  <link name="Vehicle_propeller1">
    <visual>
      <origin rpy="0 0 0" xyz="0 0 0"/>
      <geometry>
        <mesh filename="robot/UW_Vehicle/Vehicle_propeller_New.3ds"/>
      </geometry>
    </visual>
  </link>

  <joint name="Slew" type="revolute">
    <parent link="base_link"/>
    <child link="Vehicle_propeller1"/>
    <origin rpy="1 0 0" xyz="-38.3862 -9.14989 -2.62531"/>
    <limit effort="1000.0" lower="-3.14" upper="3.14" velocity="1.0"/>
  </joint>

  <link name="Vehicle_propeller2">
    <visual>
      <origin rpy="0 0 0" xyz="0 0 0"/>
      <geometry>
        <mesh filename="robot/UW_Vehicle/Vehicle_propeller_New.3ds"/>
      </geometry>
    </visual>
  </link>

  <joint name="Propeller2_body" type="revolute">
    <parent link="base_link"/>
    <child link="Vehicle_propeller2"/>
    <origin rpy="1 0 0" xyz="-38.388 9.693379 -2.36960"/> 
    <limit effort="1000.0" lower="-3.14" upper="3.14" velocity="1.0"/>
    <mimic joint="Slew" multiplier="1" offset="0"/>
  </joint>

  <link name="End_part">
    <visual>
      <origin rpy="0 0 0" xyz="0 0 0"/> 
      <geometry>
        <mesh filename="robot/UW_Vehicle/UWVehicle_endpart.3ds"/>
      </geometry>
    </visual>
  </link>

  <joint name="Shoulder" type="revolute">
    <parent link="base_link"/>
    <child link="End_part"/>
    <axis xyz="0 1 0"/>
    <origin rpy="0 0 0" xyz="-48 0 -2.51145"/>
    <limit effort="1000.0" lower="-3.14" upper="3.14" velocity="1.0"/>
  </joint>

  <link name="Camera_holder1">
    <visual>
      <origin rpy="0 0 0" xyz="0 0 0"/> 
      <geometry>
        <mesh filename="robot/UW_Vehicle/Camera_Holder.3ds"/>
      </geometry>
    </visual>
  </link>

  <joint name="Elbow" type="continuous">
    <parent link="base_link"/>
    <child link="Camera_holder1"/>
    <origin rpy="0 0 0" xyz="-5 3.17262 -7.69527"/> 
  </joint>

  <link name="Camera_holder2">
    <visual>
      <origin rpy="0 0 0" xyz="0 0 0"/> 
      <geometry>
        <mesh filename="robot/UW_Vehicle/Camera_Holder.3ds"/>
      </geometry>
    </visual>
  </link>

  <joint name="2nd_holder_to_vehicle" type="continuous">
    <parent link="base_link"/>
    <child link="Camera_holder2"/>
    <origin rpy="0 0 0" xyz="-5 -3.17262 -7.69527"/>
    <mimic joint="Elbow" multiplier="1" offset="0"/>
  </joint>

  <link name="Camera_holder5">
    <visual>
      <origin rpy="0 0 0" xyz="0 0 0"/>
      <geometry>
        <mesh filename="robot/UW_Vehicle/Camera_Holder.3ds"/>
      </geometry>
    </visual>
  </link>

  <joint name="5th_holder_to_vehicle" type="continuous">
    <parent link="base_link"/>
    <child link="Camera_holder5"/>
    <origin rpy="0 0 0" xyz="-40 3.17262 -7.69527"/>
    <!-- x era 0.07-->
    <mimic joint="Elbow" multiplier="1" offset="0"/>
  </joint>

  <link name="Camera_holder6">
    <visual>
      <origin rpy="0 0 0" xyz="0 0 0"/>
      <geometry>
        <mesh filename="robot/UW_Vehicle/Camera_Holder.3ds"/>
      </geometry>
    </visual>
  </link>

  <joint name="6th_holder_to_vehicle" type="continuous">
    <parent link="base_link"/>
    <child link="Camera_holder6"/>
    <origin rpy="0 0 0" xyz="-40 -3.17262 -7.69527"/>
    <mimic joint="Elbow" multiplier="1" offset="0"/>
  </joint>

  <link name="bottom_camera_link">
    <visual>
      <origin rpy="0 0 0" xyz="0 0 0"/>
      <geometry>
        <mesh filename="robot/UW_Vehicle/Bottom_Camera_holder.3ds"/>
      </geometry>
    </visual>
  </link>

  <joint name="JawRotate" type="revolute">
    <parent link="base_link"/>
    <child link="bottom_camera_link"/>
    <axis xyz="0 -1 0"/>
    <origin rpy="0 0 0" xyz="-1.41377 0 -8.43791"/>
    <limit effort="1000.0" lower="0" upper="1.57" velocity="1.0"/> 
  </joint>

  <link name="bottom_camera_link2">
    <visual>
      <origin rpy="0 0 0" xyz="0 0 0"/>
      <geometry>
        <mesh filename="robot/UW_Vehicle/Bottom_Camera_holder2.3ds"/>
      </geometry>
    </visual>
  </link>

  <joint name="JawRotate_Mimic" type="revolute">
    <parent link="bottom_camera_link"/>
    <child link="bottom_camera_link2"/>
    <axis xyz="0 -1 0"/>
    <origin rpy="0 0 0" xyz="-41.63106 0 -1.710"/>
    <limit effort="1000.0" lower="0" upper="1.57" velocity="1.0"/>
    <mimic joint="JawRotate" multiplier="3" offset="0"/> 
  </joint>

  <link name="bottom_camera_holder">
    <visual>
      <origin rpy="0 0 0" xyz="0 0 0"/>
      <geometry>
        <mesh filename="robot/UW_Vehicle/Bottom_camera_holder_cube.3ds"/>
      </geometry>
    </visual>
  </link>

  <joint name="camera_holder_to_bottom_camera" type="fixed">
    <parent link="bottom_camera_link2"/>
    <child link="bottom_camera_holder"/>
    <axis xyz="0 1 0"/>
    <origin rpy="0 0 0" xyz="40 0 0"/>
    <limit effort="1000.0" lower="0" upper="12.56" velocity="1.0"/>
    <mimic joint="JawRotate_Mimic" multiplier="1" offset="0"/> 
  </joint>
</robot>

