<?xml version="1.0" ?>
<!-- =================================================================================== -->
<!-- |    This document was autogenerated by xacro from Fish1.xacro                    | -->
<!-- |    EDITING THIS FILE BY HAND IS NOT RECOMMENDED                                 | -->
<!-- =================================================================================== -->
<robot name="tortoise" xmlns:xacro="http://www.ros.org/wiki/xacro">
  <link name="base_link">
    <visual>
      <origin rpy="0 0 0" xyz="0 0 0"/>
      <geometry>
        <mesh filename="package://uwsim_models/Tortoise/Tortoise_model/Tortoise_Body.dae"/>
      </geometry>
    </visual>
  </link>

  <link name="tortoise_right_front_leg">
    <visual>
      <origin rpy="0 0 0" xyz="0 0 0"/>
      <geometry>
        <mesh filename="package://uwsim_models/Tortoise/Tortoise_model/Tortoise_RightFrontleg.dae"/>
      </geometry>
    </visual>
  </link>

  <joint name="Slew" type="revolute">
    <parent link="base_link"/>
    <child link="tortoise_right_front_leg"/>
    <axis xyz="1 0 0"/>
    <origin rpy="0 0 0" xyz="-0.1733 -0.24157 0.23369"/>
    <limit effort="1000.0" lower="-1" upper="1" velocity="1.0"/>
  </joint>

  <link name="tortoise_left_front_leg">
    <visual>
      <origin rpy="0 0 0" xyz="0 0 0"/>
      <geometry>
        <mesh filename="package://uwsim_models/Tortoise/Tortoise_model/Tortoise_LeftFrontleg.dae"/>
      </geometry>
    </visual>
  </link>

  <joint name="Shoulder" type="revolute">
    <parent link="base_link"/>
    <child link="tortoise_left_front_leg"/>
    <axis xyz="1 0 0"/>
    <origin rpy="0 0 0" xyz="0.22427 -0.24346 0.233505"/>
    <limit effort="1000.0" lower="-1" upper="1" velocity="1.0"/>
  </joint>

  <link name="tortoise_right_rear_leg">
    <visual>
      <origin rpy="0 0 0" xyz="0 0 0"/>
      <geometry>
        <mesh filename="package://uwsim_models/Tortoise/Tortoise_model/Tortoise_RightRearleg.dae"/>
      </geometry>
    </visual>
  </link>

  <joint name="Elbow" type="revolute">
    <parent link="base_link"/>
    <child link="tortoise_right_rear_leg"/>
    <axis xyz="1 0 0"/>
    <origin rpy="0 0 0" xyz="-0.17700 0.44157 0.08757"/>
    <limit effort="1000.0" lower="-0.5" upper="0.5" velocity="1.0"/>
  </joint>

  <link name="tortoise_left_rear_leg">
    <visual>
      <origin rpy="0 0 0" xyz="0 0 0"/>
      <geometry>
        <mesh filename="package://uwsim_models/Tortoise/Tortoise_model/Tortoise_LeftRearleg.dae"/>
      </geometry>
    </visual>
  </link>

  <joint name="JawRotate" type="revolute">
    <parent link="base_link"/>
    <child link="tortoise_left_rear_leg"/>
    <axis xyz="1 0 0"/>
    <origin rpy="0 0 0" xyz="0.17831 0.43039 0.08730"/>
    <limit effort="1000.0" lower="-0.5" upper="0.5" velocity="1.0"/>
  </joint>

</robot>

